"use strict";(self.webpackChunkpro192_course=self.webpackChunkpro192_course||[]).push([[239],{1126:(e,t,l)=>{l.d(t,{A:()=>m});var a=l(6540),n=Object.defineProperty,r=Object.getOwnPropertySymbols,c=Object.prototype.hasOwnProperty,o=Object.prototype.propertyIsEnumerable,i=(e,t,l)=>t in e?n(e,t,{enumerable:!0,configurable:!0,writable:!0,value:l}):e[t]=l;const m=e=>{var t=e,{src:l,alt:n,width:m,height:s,loading:h="lazy",className:u=""}=t,d=((e,t)=>{var l={};for(var a in e)c.call(e,a)&&t.indexOf(a)<0&&(l[a]=e[a]);if(null!=e&&r)for(var a of r(e))t.indexOf(a)<0&&o.call(e,a)&&(l[a]=e[a]);return l})(t,["src","alt","width","height","loading","className"]);return a.createElement("img",((e,t)=>{for(var l in t||(t={}))c.call(t,l)&&i(e,l,t[l]);if(r)for(var l of r(t))o.call(t,l)&&i(e,l,t[l]);return e})({src:l,alt:n,width:m,height:s,loading:h,className:u},d))}},2239:(e,t,l)=>{l.r(t),l.d(t,{default:()=>r});var a=l(6540),n=l(1126);const r=()=>a.createElement("div",{className:"info-section p-4 mb-4 bg-white dark:bg-gray-800 rounded shadow"},a.createElement("nav",{className:"mb-6"},a.createElement("h2",{className:"text-2xl font-bold mb-2"},"Exception"),a.createElement("a",{href:"#exception",className:"text-blue-600 hover:underline mr-2"},"What Is an Exception"),"|",a.createElement("a",{href:"#kind",className:"text-blue-600 hover:underline mx-2"},"Kinds of Exception"),"|",a.createElement("a",{href:"#fix",className:"text-blue-600 hover:underline mx-2"},"How to fix"),"|",a.createElement("a",{href:"#example",className:"text-blue-600 hover:underline mx-2"},"Examples"),"|",a.createElement("a",{href:"#workshop",className:"text-blue-600 hover:underline ml-2"},"Workshop")),a.createElement("section",null,a.createElement("a",{id:"exception"}),a.createElement("h2",{className:"text-xl font-semibold mb-2"},"Exception"),a.createElement("p",null,"An exception is an event, which occurs during the execution of a program, that disrupts the normal flow of the program's instructions."),a.createElement("p",null,"When an error occurs within a method, the method creates an object and hands it off to the runtime system. The object, called an exception object, contains information about the error, including its type and the state of the program when the error occurred. Creating an exception object and handing it to the runtime system is called throwing an exception.",a.createElement("br",null),a.createElement("em",null,"[for ",a.createElement("a",{href:"http://docs.oracle.com/javase/tutorial/essential/exceptions/index.html",target:"_blank",className:"text-blue-600 underline"},"detail"),"]")),a.createElement("p",{className:"mt-4"},"For example:",a.createElement("br",null),"a user might type an invalid filename;",a.createElement("br",null),"An accessed file does not exist or might contain corrupted data;",a.createElement("br",null),"a network link could fail;",a.createElement("br",null),"\u2026",a.createElement("br",null),a.createElement("br",null),"Circumstances of this type are called exception conditions in Java and are represented using objects (All exceptions descend from the java.lang.Throwable).",a.createElement("br",null),a.createElement("br",null),"Consider the code that cause an exception:",a.createElement("br",null),a.createElement("div",{className:"flex justify-center"},a.createElement(n.A,{src:"/media/exception.webp",alt:"exception code example",className:"my-4",width:400,height:250,loading:"lazy"})),"At the row 4, the method main causes one error and this method creates an exception object, its type is ArithmaticException. And then JVM will throw it to the method main. Because the method main we do nothing to control this error, the output looks like this.",a.createElement("br",null),a.createElement("br",null),"when the error occurs at the row 4, the statement at the row 5 is dismissed."),a.createElement("a",{id:"kind"}),a.createElement("h2",{className:"text-xl font-semibold mb-2 mt-8"},"Kinds of Exception"),a.createElement("span",{className:"font-semibold"},"Checked exception"),a.createElement("br",null),a.createElement("br",null),"Checked exceptions are the exceptions that are checked at compile time. You must handle them by either the try-catch mechanism or the throws-declaration mechanism.",a.createElement("br",null),a.createElement("br",null),a.createElement("em",null,"for example:"),a.createElement("br",null),a.createElement("div",{className:"flex justify-center"},a.createElement(n.A,{src:"/media/exception2.webp",alt:"checked exception example",className:"my-4",width:400,height:250,loading:"lazy"})),"In the above example, the method FileReader() is throwing an exception to here. So, you must use try-catch mechanism or throws mechanism to handle.",a.createElement("br",null),a.createElement("br",null),a.createElement("span",{className:"font-semibold"},"Unchecked exception"),a.createElement("br",null),a.createElement("br",null),"An unchecked exception is an exception that occurs at the time of execution. These are also called as Runtime Exceptions. The program won\u2019t give a compilation error. Most of the times these exception occurs due to the bad data provided by user during the user-program interaction.",a.createElement("br",null),a.createElement("em",null,"for example:"),a.createElement("br",null),a.createElement("div",{className:"flex justify-center"},a.createElement(n.A,{src:"/media/exception1.webp",alt:"unchecked exception example",className:"my-4",width:400,height:250,loading:"lazy"})),a.createElement("br",null),"If you have declared an array of size 5 in your program, and trying to call the 6th element of the array then an error occurs.",a.createElement("br",null),a.createElement("br",null),a.createElement("em",null,"[for ",a.createElement("a",{href:"https://stackify.com/types-of-exceptions-java/",target:"_blank",className:"text-blue-600 underline"},"detail"),"]"),a.createElement("br",null),a.createElement("br",null),a.createElement("a",{id:"fix"}),a.createElement("h2",{className:"text-xl font-semibold mb-2 mt-8"},"How to fix"),"We can use try-catch mechanism or throws mechanism to handle to avoid this error.",a.createElement("br",null),a.createElement("br",null),a.createElement("span",{className:"font-semibold"},"try-catch mechanism"),a.createElement("br",null),a.createElement("br",null),"Consider the flow and syntax:",a.createElement("br",null),a.createElement("div",{className:"flex justify-center"},a.createElement(n.A,{src:"/media/exception3.webp",alt:"try-catch syntax",className:"my-4",width:400,height:250,loading:"lazy"})),a.createElement("br",null),"The ",a.createElement("em",null,"try")," statement allows you to define a block of code to be tested for errors while it is being executed.",a.createElement("br",null),a.createElement("br",null),"The ",a.createElement("em",null,"catch")," statement allows you to define a block of code to be executed, if an error occurs in the try block.",a.createElement("br",null),a.createElement("br",null),"The ",a.createElement("em",null,"finally")," statement lets you execute code, after try...catch, regardless of the result.",a.createElement("br",null),a.createElement("br",null),a.createElement("div",{className:"bg-yellow-200 dark:bg-yellow-700 text-yellow-900 dark:text-yellow-100 border-l-4 border-yellow-500 dark:border-yellow-400 px-4 py-2 my-4 rounded shadow-sm font-medium"},a.createElement("span",{className:"font-bold"},"Note:")," You cannot use ",a.createElement("span",{className:"font-mono"},"finally")," without a ",a.createElement("span",{className:"font-mono"},"try")," block. The ",a.createElement("span",{className:"font-mono"},"finally")," block is optional."),"In the example ",a.createElement("b",null,"DemoException2"),", we will edit",a.createElement("br",null),a.createElement("div",{className:"flex justify-center"},a.createElement(n.A,{src:"/media/exception5.webp",alt:"DemoException2 example",className:"my-4",width:400,height:250,loading:"lazy"})),a.createElement("br",null),a.createElement("p",null,'When the program runs to the row 14, if the file name "computer.txt" does not exist then an exception object is created (its type is FileNotFoundException) by the method main and JVM will throw the object to catch block, the variable e is used to store the address of the object. In the catch block, you can use the variable e to get error information.',a.createElement("br",null),a.createElement("b",null,"The Output will be :"),a.createElement("br",null),"something are wrong",a.createElement("br",null),"try-catch is finished",a.createElement("br",null),a.createElement("br",null)),a.createElement("p",null,"In the example ",a.createElement("b",null,"ExceptionDemo_1"),", we will edit",a.createElement("br",null)),a.createElement("div",{className:"flex justify-center"},a.createElement(n.A,{src:"/media/exception4.webp",alt:"ExceptionDemo_1 example",className:"my-4",width:400,height:250,loading:"lazy"})),a.createElement("p",null,"When you try to get 6th elements, an exception object is created (its type is ArrayIndexOutOfBoundsException). JVM will throws the object to catch block.",a.createElement("br",null),a.createElement("b",null,"The output will be:"),a.createElement("br",null),"1,2,3,4,5,something are wrong",a.createElement("br",null),"try-catch is finished",a.createElement("br",null),a.createElement("br",null)),a.createElement("span",{className:"font-semibold"},"throws mechanism"),a.createElement("br",null),a.createElement("br",null),"In the example ",a.createElement("b",null,"DemoException2"),", the error occurs in the main, to fix a checked exception we use ",a.createElement("b",null,"throws")," keyword. We will edit:",a.createElement("br",null),a.createElement("div",{className:"flex justify-center"},a.createElement(n.A,{src:"/media/exception6.webp",alt:"throws mechanism example",className:"my-4",width:400,height:250,loading:"lazy"})),a.createElement("b",null,"The output will be:"),' something are wrong if the file name "computer.txt" does not exist.',a.createElement("a",{id:"example"}),a.createElement("h2",{className:"text-xl font-semibold mb-2 mt-8"},"Examples"),'The code below to print out "age is 20 or older" if age is below 20 or input a text.',a.createElement("br",null),a.createElement("div",{className:"flex justify-center"},a.createElement(n.A,{src:"/media/exception7.webp",alt:"age example code",className:"my-4",width:400,height:250,loading:"lazy"})),a.createElement("br",null),'When the code runs to the row 20, if you input a text "hello" then this method will create an exception object and JVM will throw it to the catch block to handle. The output will be :',a.createElement("div",{className:"flex justify-center"},a.createElement(n.A,{src:"/media/exception8.webp",alt:"output for hello input",className:"my-4 inline",width:400,height:250,loading:"lazy"})),a.createElement("br",null),"If you input 18 then the statement ",a.createElement("b",null,"throw new Exception()")," will create an exception object. This object will be thrown to the catch block. The output will be:",a.createElement("br",null),a.createElement("div",{className:"flex justify-center"},a.createElement(n.A,{src:"/media/exception9.webp",alt:"output for 18 input",className:"my-4 inline",width:400,height:250,loading:"lazy"})),a.createElement("br",null),a.createElement("span",{className:"font-semibold mt-8"},"Summary"),a.createElement("br",null),a.createElement("br",null),a.createElement("ul",{className:"list-disc list-inside mb-4"},a.createElement("li",null,"A try block is always followed by a catch block, which handles the exception that occurs in associated try block."),a.createElement("li",null,"A single try block can have multiple catch blocks associated with it. see ",a.createElement("em",null,a.createElement("b",null,a.createElement("a",{href:"https://docs.oracle.com/javase/7/docs/technotes/guides/language/catch-multiple.html",target:"_blank",className:"text-blue-600 underline"},"catching multiple exceptions in java.")))),a.createElement("li",null,"A try statement may be nested inside either the try or catch block of another try statement. see ",a.createElement("em",null,a.createElement("b",null,a.createElement("a",{href:"https://beginnersbook.com/2013/04/nested-try-catch/#:~:text=When%20a%20try%20catch%20block,that%20that%20catch%20block%20executes.",target:"_blank",className:"text-blue-600 underline"},"Nesting of try/catch Blocks")))),a.createElement("li",null,"When you write a method that causes an exception. If you do not want to handle this error you can throw it to another method to handle the error by using throws keyword"),a.createElement("li",null,"You can create your own exception Classes, see ",a.createElement("a",{href:"https://www.javatpoint.com/custom-exception",target:"_blank",className:"text-blue-600 underline"},"Custom Exception Classes"))),a.createElement("h2",{className:"text-xl font-semibold mb-2 mt-8"},"Course slide"),a.createElement("ul",{className:"list-disc list-inside mb-4"},a.createElement("li",null,a.createElement("a",{href:"/resource/Exception Handling.pdf",download:!0,className:"text-blue-600 underline"},"Exceptions.pdf"))),a.createElement("a",{id:"workshop"}),a.createElement("h2",{className:"text-xl font-semibold mb-2 mt-8"},"Workshop"),a.createElement("ul",{className:"list-disc list-inside mb-4"},a.createElement("li",null,"Complete the ",a.createElement("a",{href:"/workshop/workshop2.pdf",download:!0,className:"text-blue-600 underline"},"workshop2")))))}}]);